<?xml version='1.0'?>


<robot name="robot_car" xmlns:xacro="http://www.ros.org/wiki/xacro">
<!--   <xacro:include filename="$(find epi1)/models/robot_car/robot_car.gazebo" /> -->
  
  <gazebo reference="base_link">
    <material>Gazebo/Orange</material>
  </gazebo>

  <xacro:property name="x_chassis" value="0.5" />
  <xacro:property name="y_chassis" value="0.3" />
  <xacro:property name="z_chassis" value="0.15" />
  <xacro:property name="m_chassis" value="10.0" />
  
  <!-- Parameter for the wheels, radius [m], height [m], mass [kg], torque [Nm], wheelbase [m] -->
  <xacro:property name="r_wheel" value="0.1075"/>
  <xacro:property name="h_wheel" value="0.03" />
  <xacro:property name="m_wheel" value="3.0" /> 
  <xacro:property name="torque_wheel" value="10" />
  <xacro:property name="L_wheel" value="0.1788" />

  <xacro:macro name="box_inertia" params="m x y z">
      <inertia  
        ixx="${m*(y*y+z*z)/12}" ixy = "0" ixz = "0"
        iyy="${m*(x*x+z*z)/12}" iyz = "0"
        izz="${m*(x*x+z*z)/12}"
      />
  </xacro:macro>

  <xacro:macro name="cylinder_inertia" params="m r h">
    <inertia  
      ixx="${m*(3*r*r+h*h)/12}" ixy = "0" ixz = "0"
      iyy="${m*(3*r*r+h*h)/12}" iyz = "0"
      izz="${m*r*r/2}"
    />
  </xacro:macro>
 
  <link name='base_link'>
    <pose>0 0 0 0 0 0</pose>
  </link>
  <joint type="fixed" name="base_link_to_chassis">
    <child link="chassis_link"/>
    <parent link="base_link"/>
  </joint>

  <!-- Define the chassis of the differential drive robot, which is our base -->
  <link name='chassis_link'>
    <pose>0 0 0 0 0 0</pose>
    <!-- Define inertial system for the chassis -->
    <inertial>
      <mass value="${m_chassis}"/>
      <xacro:box_inertia m="${m_chassis}" x="${x_chassis}" y="${y_chassis}" z="${z_chassis}"/>
    </inertial>
    <!-- Define collision sorrounding box -->
    <collision name='collision'>
      <origin xyz="0 0 0" rpy=" 0 0 0"/>
      <geometry>
        <box size="${x_chassis} ${y_chassis} ${z_chassis}"/>
      </geometry>
    </collision>
    <!-- Define visualization structure -->
    <visual name='base_link_visual'>
	  <origin xyz="0 0 0" rpy=" 0 0 0"/>
      <geometry>
        <box size="${x_chassis} ${y_chassis} ${z_chassis}"/>
      </geometry>
    </visual>

    <!-- Add the caster wheel! Here we simply assume complete slippage, thus we do not require that it rotates! -->
    <collision name='caster_collision'>
      <origin xyz="${-(r_wheel/2)+x_chassis/2} 0 ${-z_chassis/2}" rpy=" 0 0 0"/>
      <geometry>
        <sphere radius="${r_wheel/2}"/>
      </geometry>
      <surface>
        <friction>
          <ode>
            <mu>0</mu>
            <mu2>0</mu2>
            <slip1>1.0</slip1>
            <slip2>1.0</slip2>
          </ode>
        </friction>
      </surface>
    </collision>
    <visual name='caster_visual'>
      <origin xyz="${-(r_wheel/2)+x_chassis/2} 0 ${-z_chassis/2}" rpy=" 0 0 0"/>
      <geometry>
        <sphere radius="${r_wheel/2}"/>
      </geometry>
    </visual>
  </link>

  <!-- Add the wheels for the robot -->
  <link name="left_wheel">
    <collision name="collision">
      <origin xyz="0 0 0" rpy="0 1.5707 1.5707"/>
      <geometry>
        <cylinder radius="${r_wheel}" length="${h_wheel}"/>
      </geometry>
      <surface>
        <friction>
          <ode>
            <mu>1.0</mu>
            <mu2>1.0</mu2>
            <slip1>0.0</slip1>
            <slip2>0.0</slip2>
          </ode>
        </friction>
      </surface>
    </collision>
    <visual name="left_wheel_visual">
      <origin xyz="0 0 0" rpy="0 1.5707 1.5707"/>
      <geometry>
        <cylinder radius="${r_wheel}" length="${h_wheel}"/>
      </geometry>
    </visual>
    <inertial>
      <origin xyz="0 0 0" rpy="0 1.5707 1.5707"/>
      <mass value="${m_wheel}"/>
      <xacro:cylinder_inertia m="${m_wheel}" r="${r_wheel}" h="${h_wheel}"/>
    </inertial>
  </link>

  <link name="right_wheel">
    <collision name="collision">
      <origin xyz="0 0 0" rpy="0 1.5707 1.5707"/>
      <geometry>
        <cylinder radius="${r_wheel}" length="${h_wheel}"/>
      </geometry>
      <surface>
        <friction>
          <ode>
            <mu>1.0</mu>
            <mu2>1.0</mu2>
            <slip1>0.0</slip1>
            <slip2>0.0</slip2>
          </ode>
        </friction>
      </surface>
    </collision>
    <visual name="right_wheel_visual">
      <origin xyz="0 0 0" rpy="0 1.5707 1.5707"/>
      <geometry>
        <cylinder radius="${r_wheel}" length="${h_wheel}"/>
      </geometry>
    </visual>
    <inertial>
      <origin xyz="0 0 0" rpy="0 1.5707 1.5707"/>
      <mass value="${m_wheel}"/>
      <xacro:cylinder_inertia m="${m_wheel}" r="${r_wheel}" h="${h_wheel}"/>
    </inertial>
  </link>

  <!-- Set joints for the wheels which can be controlled over ROS -->
  <joint type="continuous" name="left_wheel_hinge">
    <origin xyz="${-x_chassis/4} ${y_chassis/2+h_wheel/2} ${r_wheel/2-z_chassis/2}" rpy="0 0 0"/>
    <child link="left_wheel"/>
    <parent link="base_link"/>
    <axis xyz="0 1 0" rpy="0 0 0"/>
    <limit effort="100" velocity="100"/>
    <joint_properties damping="0.0" friction="0.0"/>
  </joint>
  <joint type="continuous" name="right_wheel_hinge">
    <origin xyz="${-x_chassis/4} ${-y_chassis/2-h_wheel/2} ${r_wheel/2-z_chassis/2}" rpy="0 0 0"/>
    <child link="right_wheel"/>
    <parent link="base_link"/>
    <axis xyz="0 1 0" rpy="0 0 0"/>
    <limit effort="100" velocity="100"/>
    <joint_properties damping="0.0" friction="0.0"/>
  </joint>
</robot>
